[2024-05-31T18:29:51.457+0000] {taskinstance.py:1956} INFO - Dependencies all met for dep_context=non-requeueable deps ti=<TaskInstance: etl_2.LOAD manual__2024-05-31T18:29:49.378510+00:00 [queued]>
[2024-05-31T18:29:51.465+0000] {taskinstance.py:1956} INFO - Dependencies all met for dep_context=requeueable deps ti=<TaskInstance: etl_2.LOAD manual__2024-05-31T18:29:49.378510+00:00 [queued]>
[2024-05-31T18:29:51.465+0000] {taskinstance.py:2170} INFO - Starting attempt 1 of 1
[2024-05-31T18:29:51.478+0000] {taskinstance.py:2191} INFO - Executing <Task(PythonOperator): LOAD> on 2024-05-31 18:29:49.378510+00:00
[2024-05-31T18:29:51.492+0000] {standard_task_runner.py:60} INFO - Started process 1470 to run task
[2024-05-31T18:29:51.512+0000] {standard_task_runner.py:87} INFO - Running: ['***', 'tasks', 'run', 'etl_2', 'LOAD', 'manual__2024-05-31T18:29:49.378510+00:00', '--job-id', '15', '--raw', '--subdir', 'DAGS_FOLDER/etl.py', '--cfg-path', '/tmp/tmpis6kmaop']
[2024-05-31T18:29:51.526+0000] {standard_task_runner.py:88} INFO - Job 15: Subtask LOAD
[2024-05-31T18:29:51.697+0000] {task_command.py:423} INFO - Running <TaskInstance: etl_2.LOAD manual__2024-05-31T18:29:49.378510+00:00 [running]> on host 503e112b7b7d
[2024-05-31T18:29:51.867+0000] {taskinstance.py:2480} INFO - Exporting env vars: AIRFLOW_CTX_DAG_OWNER='ashish' AIRFLOW_CTX_DAG_ID='etl_2' AIRFLOW_CTX_TASK_ID='LOAD' AIRFLOW_CTX_EXECUTION_DATE='2024-05-31T18:29:49.378510+00:00' AIRFLOW_CTX_TRY_NUMBER='1' AIRFLOW_CTX_DAG_RUN_ID='manual__2024-05-31T18:29:49.378510+00:00'
[2024-05-31T18:29:51.886+0000] {taskinstance.py:2698} ERROR - Task failed with exception
Traceback (most recent call last):
  File "/home/airflow/.local/lib/python3.8/site-packages/airflow/models/taskinstance.py", line 433, in _execute_task
    result = execute_callable(context=context, **execute_callable_kwargs)
  File "/home/airflow/.local/lib/python3.8/site-packages/airflow/operators/python.py", line 199, in execute
    return_value = self.execute_callable()
  File "/home/airflow/.local/lib/python3.8/site-packages/airflow/operators/python.py", line 216, in execute_callable
    return self.python_callable(*self.op_args, **self.op_kwargs)
  File "/opt/airflow/dags/etl.py", line 28, in load_fun
    print(f'the value of xcom is {xcom_pull_obj[0]}')
  File "/home/airflow/.local/lib/python3.8/site-packages/airflow/models/xcom.py", line 795, in __getitem__
    raise IndexError(key) from None
IndexError: 0
[2024-05-31T18:29:51.912+0000] {taskinstance.py:1138} INFO - Marking task as FAILED. dag_id=etl_2, task_id=LOAD, execution_date=20240531T182949, start_date=20240531T182951, end_date=20240531T182951
[2024-05-31T18:29:51.929+0000] {standard_task_runner.py:107} ERROR - Failed to execute job 15 for task LOAD (0; 1470)
[2024-05-31T18:29:51.965+0000] {local_task_job_runner.py:234} INFO - Task exited with return code 1
[2024-05-31T18:29:51.986+0000] {taskinstance.py:3280} INFO - 0 downstream tasks scheduled from follow-on schedule check
