[2024-05-31T18:59:52.816+0000] {taskinstance.py:1956} INFO - Dependencies all met for dep_context=non-requeueable deps ti=<TaskInstance: etl_2.LOAD manual__2024-05-31T18:59:40.043798+00:00 [queued]>
[2024-05-31T18:59:52.828+0000] {taskinstance.py:1956} INFO - Dependencies all met for dep_context=requeueable deps ti=<TaskInstance: etl_2.LOAD manual__2024-05-31T18:59:40.043798+00:00 [queued]>
[2024-05-31T18:59:52.829+0000] {taskinstance.py:2170} INFO - Starting attempt 1 of 1
[2024-05-31T18:59:52.853+0000] {taskinstance.py:2191} INFO - Executing <Task(PythonOperator): LOAD> on 2024-05-31 18:59:40.043798+00:00
[2024-05-31T18:59:52.865+0000] {standard_task_runner.py:60} INFO - Started process 2051 to run task
[2024-05-31T18:59:52.869+0000] {standard_task_runner.py:87} INFO - Running: ['***', 'tasks', 'run', 'etl_2', 'LOAD', 'manual__2024-05-31T18:59:40.043798+00:00', '--job-id', '60', '--raw', '--subdir', 'DAGS_FOLDER/etl.py', '--cfg-path', '/tmp/tmpg_s0e_nj']
[2024-05-31T18:59:52.873+0000] {standard_task_runner.py:88} INFO - Job 60: Subtask LOAD
[2024-05-31T18:59:52.947+0000] {task_command.py:423} INFO - Running <TaskInstance: etl_2.LOAD manual__2024-05-31T18:59:40.043798+00:00 [running]> on host 503e112b7b7d
[2024-05-31T18:59:53.037+0000] {taskinstance.py:2480} INFO - Exporting env vars: AIRFLOW_CTX_DAG_OWNER='ashish' AIRFLOW_CTX_DAG_ID='etl_2' AIRFLOW_CTX_TASK_ID='LOAD' AIRFLOW_CTX_EXECUTION_DATE='2024-05-31T18:59:40.043798+00:00' AIRFLOW_CTX_TRY_NUMBER='1' AIRFLOW_CTX_DAG_RUN_ID='manual__2024-05-31T18:59:40.043798+00:00'
[2024-05-31T18:59:53.049+0000] {taskinstance.py:2698} ERROR - Task failed with exception
Traceback (most recent call last):
  File "/home/airflow/.local/lib/python3.8/site-packages/airflow/models/taskinstance.py", line 433, in _execute_task
    result = execute_callable(context=context, **execute_callable_kwargs)
  File "/home/airflow/.local/lib/python3.8/site-packages/airflow/operators/python.py", line 199, in execute
    return_value = self.execute_callable()
  File "/home/airflow/.local/lib/python3.8/site-packages/airflow/operators/python.py", line 216, in execute_callable
    return self.python_callable(*self.op_args, **self.op_kwargs)
  File "/opt/airflow/dags/etl.py", line 32, in load_fun
    transform_value = xcom_pull_obj[0]
TypeError: 'int' object is not subscriptable
[2024-05-31T18:59:53.061+0000] {taskinstance.py:1138} INFO - Marking task as FAILED. dag_id=etl_2, task_id=LOAD, execution_date=20240531T185940, start_date=20240531T185952, end_date=20240531T185953
[2024-05-31T18:59:53.076+0000] {standard_task_runner.py:107} ERROR - Failed to execute job 60 for task LOAD ('int' object is not subscriptable; 2051)
[2024-05-31T18:59:53.122+0000] {local_task_job_runner.py:234} INFO - Task exited with return code 1
[2024-05-31T18:59:53.141+0000] {taskinstance.py:3280} INFO - 0 downstream tasks scheduled from follow-on schedule check
