[2024-05-31T18:39:27.548+0000] {taskinstance.py:1956} INFO - Dependencies all met for dep_context=non-requeueable deps ti=<TaskInstance: etl_2.LOAD manual__2024-05-31T18:39:21.777996+00:00 [queued]>
[2024-05-31T18:39:27.572+0000] {taskinstance.py:1956} INFO - Dependencies all met for dep_context=requeueable deps ti=<TaskInstance: etl_2.LOAD manual__2024-05-31T18:39:21.777996+00:00 [queued]>
[2024-05-31T18:39:27.573+0000] {taskinstance.py:2170} INFO - Starting attempt 1 of 1
[2024-05-31T18:39:27.617+0000] {taskinstance.py:2191} INFO - Executing <Task(PythonOperator): LOAD> on 2024-05-31 18:39:21.777996+00:00
[2024-05-31T18:39:27.645+0000] {standard_task_runner.py:60} INFO - Started process 1667 to run task
[2024-05-31T18:39:27.649+0000] {standard_task_runner.py:87} INFO - Running: ['***', 'tasks', 'run', 'etl_2', 'LOAD', 'manual__2024-05-31T18:39:21.777996+00:00', '--job-id', '31', '--raw', '--subdir', 'DAGS_FOLDER/etl.py', '--cfg-path', '/tmp/tmp7ibhtpfy']
[2024-05-31T18:39:27.657+0000] {standard_task_runner.py:88} INFO - Job 31: Subtask LOAD
[2024-05-31T18:39:27.756+0000] {task_command.py:423} INFO - Running <TaskInstance: etl_2.LOAD manual__2024-05-31T18:39:21.777996+00:00 [running]> on host 503e112b7b7d
[2024-05-31T18:39:27.926+0000] {taskinstance.py:2480} INFO - Exporting env vars: AIRFLOW_CTX_DAG_OWNER='ashish' AIRFLOW_CTX_DAG_ID='etl_2' AIRFLOW_CTX_TASK_ID='LOAD' AIRFLOW_CTX_EXECUTION_DATE='2024-05-31T18:39:21.777996+00:00' AIRFLOW_CTX_TRY_NUMBER='1' AIRFLOW_CTX_DAG_RUN_ID='manual__2024-05-31T18:39:21.777996+00:00'
[2024-05-31T18:39:27.948+0000] {taskinstance.py:2698} ERROR - Task failed with exception
Traceback (most recent call last):
  File "/home/airflow/.local/lib/python3.8/site-packages/airflow/models/taskinstance.py", line 433, in _execute_task
    result = execute_callable(context=context, **execute_callable_kwargs)
  File "/home/airflow/.local/lib/python3.8/site-packages/airflow/operators/python.py", line 199, in execute
    return_value = self.execute_callable()
  File "/home/airflow/.local/lib/python3.8/site-packages/airflow/operators/python.py", line 216, in execute_callable
    return self.python_callable(*self.op_args, **self.op_kwargs)
  File "/opt/airflow/dags/etl.py", line 28, in load_fun
    print(f'the value of xcom is {xcom_pull_obj[1]}')
  File "/home/airflow/.local/lib/python3.8/site-packages/airflow/models/xcom.py", line 795, in __getitem__
    raise IndexError(key) from None
IndexError: 1
[2024-05-31T18:39:27.962+0000] {taskinstance.py:1138} INFO - Marking task as FAILED. dag_id=etl_2, task_id=LOAD, execution_date=20240531T183921, start_date=20240531T183927, end_date=20240531T183927
[2024-05-31T18:39:27.987+0000] {standard_task_runner.py:107} ERROR - Failed to execute job 31 for task LOAD (1; 1667)
[2024-05-31T18:39:28.025+0000] {local_task_job_runner.py:234} INFO - Task exited with return code 1
[2024-05-31T18:39:28.072+0000] {taskinstance.py:3280} INFO - 0 downstream tasks scheduled from follow-on schedule check
